<?xml version="1.0" ?>
<!-- =================================================================================== -->
<!-- |    This document was autogenerated by xacro from /simply_ws/src/interbotix/interbotix_ros_rovers/interbotix_ros_xslocobots/interbotix_xslocobot_descriptions/urdf/locobot.urdf.xacro | -->
<!-- |    EDITING THIS FILE BY HAND IS NOT RECOMMENDED                                 | -->
<!-- =================================================================================== -->
<robot name="locobot">
  <material name="interbotix_black">
    <texture filename="package://interbotix_common_sim/media/materials/textures/interbotix_black.png"/>
  </material>
  <!-- kobuki -->
  <!-- create3 -->
  <!-- ********************************** Plate **********************************  -->
  <!-- base_type ==
  'kobuki' -->
  <!-- base_type ==
  'create3' -->
  <!-- ********************************** Arm ********************************** -->
  <!-- base_type == 'kobuki' -->
  <!-- base_type == 'create3' -->
  <!-- If the AR tag is being used, then add the AR tag mount -->
  <joint name="ar_tag" type="fixed">
    <axis xyz="0 0 0"/>
    <origin rpy="0 0 0" xyz="-0.017 0 0.04155"/>
    <parent link="_ee_arm_link"/>
    <child link="_ar_tag_link"/>
  </joint>
  <link name="_ar_tag_link">
    <visual>
      <origin rpy="0 0 0" xyz="0 0 0"/>
      <geometry>
        <mesh filename="package://interbotix_xslocobot_descriptions/meshes/mobile_wx250s_meshes/../ar_tag.stl" scale="0.001 0.001 0.001"/>
      </geometry>
      <material name="interbotix_black"/>
    </visual>
    <collision>
      <origin rpy="0 0 0" xyz="0 0 0"/>
      <geometry>
        <mesh filename="package://interbotix_xslocobot_descriptions/meshes/mobile_wx250s_meshes/../ar_tag.stl" scale="0.001 0.001 0.001"/>
      </geometry>
    </collision>
    <inertial>
      <origin rpy="0 0 0" xyz="0 0 -0.00315"/>
      <mass value="0.016507"/>
      <inertia ixx="0.000003084" ixy="0" ixz="0" iyy="0.000003084" iyz="0" izz="0.000006059"/>
    </inertial>
  </link>
  <gazebo reference="ar_tag">
    <disableFixedJointLumping>true</disableFixedJointLumping>
  </gazebo>
  <gazebo reference="_ar_tag_link">
    <material>Gazebo/DarkGrey</material>
  </gazebo>
  <!-- show_ar_tag -->
  <link name="_arm_base_link">
    <visual>
      <origin rpy="1.5707963267948966 0 1.5707963267948966" xyz="-0.095773 0 -0.10565023"/>
      <geometry>
        <mesh filename="package://interbotix_xslocobot_descriptions/meshes/mobile_wx250s_meshes/base.stl" scale="0.001 0.001 0.001"/>
      </geometry>
      <material name="interbotix_black"/>
    </visual>
    <collision>
      <origin rpy="1.5707963267948966 0 1.5707963267948966" xyz="-0.095773 0 -0.10565023"/>
      <geometry>
        <mesh filename="package://interbotix_xslocobot_descriptions/meshes/mobile_wx250s_meshes/base.stl" scale="0.001 0.001 0.001"/>
      </geometry>
    </collision>
    <inertial>
      <origin rpy="1.5707963267948966 0 1.5707963267948966" xyz="-0.0001350000 -0.0000266286 0.0338755000"/>
      <mass value="0.379673"/>
      <inertia ixx="0.0004351000" ixy="0.0000000707" ixz="0.0000000266" iyy="0.0004452000" iyz="-0.0000022881" izz="0.0005731000"/>
    </inertial>
  </link>
  <joint name="waist" type="revolute">
    <axis xyz="0 0 1"/>
    <limit effort="10.0" lower="-3.141582653589793" upper="3.141582653589793" velocity="3.141592653589793"/>
    <origin rpy="0 0 0" xyz="0 0 0.066175"/>
    <parent link="_arm_base_link"/>
    <child link="_shoulder_link"/>
    <dynamics damping="0.1" friction="0.1"/>
  </joint>
  <link name="_shoulder_link">
    <visual>
      <origin rpy="0 0 1.5707963267948966" xyz="0 0 -0.003"/>
      <geometry>
        <mesh filename="package://interbotix_xslocobot_descriptions/meshes/mobile_wx250s_meshes/shoulder.stl" scale="0.001 0.001 0.001"/>
      </geometry>
      <material name="interbotix_black"/>
    </visual>
    <collision>
      <origin rpy="0 0 1.5707963267948966" xyz="0 0 -0.003"/>
      <geometry>
        <mesh filename="package://interbotix_xslocobot_descriptions/meshes/mobile_wx250s_meshes/shoulder.stl" scale="0.001 0.001 0.001"/>
      </geometry>
    </collision>
    <inertial>
      <origin rpy="0 0 1.5707963267948966" xyz="0.0000223482 0.0000414609 0.0066287000"/>
      <mass value="0.480879"/>
      <inertia ixx="0.0003790000" ixy="0.0000000022" ixz="-0.0000003561" iyy="0.0005557000" iyz="0.0000012245" izz="0.0005889000"/>
    </inertial>
  </link>
  <joint name="shoulder" type="revolute">
    <axis xyz="0 1 0"/>
    <limit effort="20.0" lower="-1.8849555921538759" upper="1.9896753472735358" velocity="3.141592653589793"/>
    <origin rpy="0 -1.1 0" xyz="0 0 0.03865"/>
    <parent link="_shoulder_link"/>
    <child link="_upper_arm_link"/>
    <dynamics damping="0.1" friction="0.1"/>
  </joint>
  <link name="_upper_arm_link">
    <visual>
      <origin rpy="0 0 1.5707963267948966" xyz="0 0 0"/>
      <geometry>
        <mesh filename="package://interbotix_xslocobot_descriptions/meshes/mobile_wx250s_meshes/upper_arm.stl" scale="0.001 0.001 0.001"/>
      </geometry>
      <material name="interbotix_black"/>
    </visual>
    <collision>
      <origin rpy="0 0 1.5707963267948966" xyz="0 0 0"/>
      <geometry>
        <mesh filename="package://interbotix_xslocobot_descriptions/meshes/mobile_wx250s_meshes/upper_arm.stl" scale="0.001 0.001 0.001"/>
      </geometry>
    </collision>
    <inertial>
      <origin rpy="0 0 1.5707963267948966" xyz="0.0171605000 0.0000002725 0.1913230000"/>
      <mass value="0.430811"/>
      <inertia ixx="0.0034630000" ixy="-0.0000000001" ixz="-0.0000000002" iyy="0.0035870000" iyz="0.0004272000" izz="0.0004566000"/>
    </inertial>
  </link>
  <joint name="elbow" type="revolute">
    <axis xyz="0 1 0"/>
    <limit effort="15.0" lower="-2.1467549799530254" upper="1.6057029118347832" velocity="3.141592653589793"/>
    <origin rpy="0 1.55 0" xyz="0.04975 0 0.25"/>
    <parent link="_upper_arm_link"/>
    <child link="_upper_forearm_link"/>
    <dynamics damping="0.1" friction="0.1"/>
  </joint>
  <link name="_upper_forearm_link">
    <visual>
      <origin rpy="0 0 0" xyz="0 0 0"/>
      <geometry>
        <mesh filename="package://interbotix_xslocobot_descriptions/meshes/mobile_wx250s_meshes/upper_forearm.stl" scale="0.001 0.001 0.001"/>
      </geometry>
      <material name="interbotix_black"/>
    </visual>
    <collision>
      <origin rpy="0 0 0" xyz="0 0 0"/>
      <geometry>
        <mesh filename="package://interbotix_xslocobot_descriptions/meshes/mobile_wx250s_meshes/upper_forearm.stl" scale="0.001 0.001 0.001"/>
      </geometry>
    </collision>
    <inertial>
      <origin rpy="0 0 0" xyz="0.1079630000 0.0001158760 0"/>
      <mass value="0.234589"/>
      <inertia ixx="0.0000397100" ixy="0.0000023528" ixz="0" iyy="0.0008878000" iyz="0" izz="0.0008880000"/>
    </inertial>
  </link>
  <joint name="forearm_roll" type="revolute">
    <axis xyz="1 0 0"/>
    <limit effort="2.0" lower="-3.141582653589793" upper="3.141582653589793" velocity="3.141592653589793"/>
    <origin rpy="0 0 0" xyz="0.175 0 0"/>
    <parent link="_upper_forearm_link"/>
    <child link="_lower_forearm_link"/>
    <dynamics damping="0.1" friction="0.1"/>
  </joint>
  <link name="_lower_forearm_link">
    <visual>
      <origin rpy="3.141592653589793 0 0" xyz="0 0 0"/>
      <geometry>
        <mesh filename="package://interbotix_xslocobot_descriptions/meshes/mobile_wx250s_meshes/lower_forearm.stl" scale="0.001 0.001 0.001"/>
      </geometry>
      <material name="interbotix_black"/>
    </visual>
    <collision>
      <origin rpy="3.141592653589793 0 0" xyz="0 0 0"/>
      <geometry>
        <mesh filename="package://interbotix_xslocobot_descriptions/meshes/mobile_wx250s_meshes/lower_forearm.stl" scale="0.001 0.001 0.001"/>
      </geometry>
    </collision>
    <inertial>
      <origin rpy="3.141592653589793 0 0" xyz="0.0374395000 0.0052225200 0"/>
      <mass value="0.220991"/>
      <inertia ixx="0.0000636900" ixy="-0.0000229200" ixz="0" iyy="0.0001677000" iyz="0" izz="0.0001834000"/>
    </inertial>
  </link>
  <joint name="wrist_angle" type="revolute">
    <axis xyz="0 1 0"/>
    <limit effort="5.0" lower="-1.7453292519943295" upper="2.1467549799530254" velocity="3.141592653589793"/>
    <origin rpy="0 0.5 0" xyz="0.075 0 0"/>
    <parent link="_lower_forearm_link"/>
    <child link="_wrist_link"/>
    <dynamics damping="0.1" friction="0.1"/>
  </joint>
  <link name="_wrist_link">
    <visual>
      <origin rpy="0 0 1.5707963267948966" xyz="0 0 0"/>
      <geometry>
        <mesh filename="package://interbotix_xslocobot_descriptions/meshes/mobile_wx250s_meshes/wrist.stl" scale="0.001 0.001 0.001"/>
      </geometry>
      <material name="interbotix_black"/>
    </visual>
    <collision>
      <origin rpy="0 0 1.5707963267948966" xyz="0 0 0"/>
      <geometry>
        <mesh filename="package://interbotix_xslocobot_descriptions/meshes/mobile_wx250s_meshes/wrist.stl" scale="0.001 0.001 0.001"/>
      </geometry>
    </collision>
    <inertial>
      <origin rpy="0 0 1.5707963267948966" xyz="0.0423600000 -0.0000106630 0.0105770000"/>
      <mass value="0.084957"/>
      <inertia ixx="0.0000308200" ixy="0.0000000191" ixz="0.0000000023" iyy="0.0000282200" iyz="0.0000025481" izz="0.0000315200"/>
    </inertial>
  </link>
  <!-- Include the gripper if used -->
  <joint name="wrist_rotate" type="revolute">
    <axis xyz="1 0 0"/>
    <limit effort="1.0" lower="-3.141582653589793" upper="3.141582653589793" velocity="3.141592653589793"/>
    <origin rpy="0 0 0" xyz="0.065 0 0"/>
    <parent link="_wrist_link"/>
    <child link="_gripper_link"/>
    <dynamics damping="0.1" friction="0.1"/>
  </joint>
  <link name="_gripper_link">
    <visual>
      <origin rpy="0 0 1.5707963267948966" xyz="-0.02 0 0"/>
      <geometry>
        <mesh filename="package://interbotix_xslocobot_descriptions/meshes/mobile_wx250s_meshes/gripper.stl" scale="0.001 0.001 0.001"/>
      </geometry>
      <material name="interbotix_black"/>
    </visual>
    <collision>
      <origin rpy="0 0 1.5707963267948966" xyz="-0.02 0 0"/>
      <geometry>
        <mesh filename="package://interbotix_xslocobot_descriptions/meshes/mobile_wx250s_meshes/gripper.stl" scale="0.001 0.001 0.001"/>
      </geometry>
    </collision>
    <inertial>
      <origin rpy="0 0 1.5707963267948966" xyz="0.0216310000 0.0000002516 0.0114100000"/>
      <mass value="0.072885"/>
      <inertia ixx="0.0000253700" ixy="0" ixz="0" iyy="0.0000183600" iyz="0.0000004340" izz="0.0000167400"/>
    </inertial>
  </link>
  <joint name="ee_arm" type="fixed">
    <axis xyz="1 0 0"/>
    <origin rpy="0 0 0" xyz="0.043 0 0"/>
    <parent link="_gripper_link"/>
    <child link="_ee_arm_link"/>
  </joint>
  <link name="_ee_arm_link">
    <inertial>
      <mass value="0.001"/>
      <inertia ixx="0.001" ixy="0" ixz="0" iyy="0.001" iyz="0" izz="0.001"/>
    </inertial>
  </link>
  <joint name="gripper" type="continuous">
    <axis xyz="1 0 0"/>
    <limit effort="1" velocity="3.141592653589793"/>
    <origin rpy="0 0 0" xyz="0.0055 0 0"/>
    <parent link="_ee_arm_link"/>
    <child link="_gripper_prop_link"/>
    <dynamics damping="0.1" friction="0.1"/>
  </joint>
  <link name="_gripper_prop_link">
    <visual>
      <origin rpy="0 0 1.5707963267948966" xyz="-0.0685 0 0"/>
      <geometry>
        <mesh filename="package://interbotix_xslocobot_descriptions/meshes/mobile_wx250s_meshes/gripper_prop.stl" scale="0.001 0.001 0.001"/>
      </geometry>
      <material name="interbotix_black"/>
    </visual>
    <collision>
      <origin rpy="0 0 1.5707963267948966" xyz="-0.0685 0 0"/>
      <geometry>
        <mesh filename="package://interbotix_xslocobot_descriptions/meshes/mobile_wx250s_meshes/gripper_prop.stl" scale="0.001 0.001 0.001"/>
      </geometry>
    </collision>
    <inertial>
      <origin rpy="0 0 1.5707963267948966" xyz="0.0008460000 -0.0000016817 0.0000420000"/>
      <mass value="0.00434"/>
      <inertia ixx="0.0000005923" ixy="0" ixz="0.0000003195" iyy="0.0000011156" iyz="-0.0000000004" izz="0.0000005743"/>
    </inertial>
  </link>
  <!-- If the gripper bar is being used, then also add the gripper bar -->
  <joint name="gripper_bar" type="fixed">
    <axis xyz="1 0 0"/>
    <origin rpy="0 0 0" xyz="0 0 0"/>
    <parent link="_ee_arm_link"/>
    <child link="_gripper_bar_link"/>
  </joint>
  <link name="_gripper_bar_link">
    <visual>
      <origin rpy="0 0 1.5707963267948966" xyz="-0.063 0 0"/>
      <geometry>
        <mesh filename="package://interbotix_xslocobot_descriptions/meshes/mobile_wx250s_meshes/gripper_bar.stl" scale="0.001 0.001 0.001"/>
      </geometry>
      <material name="interbotix_black"/>
    </visual>
    <collision>
      <origin rpy="0 0 1.5707963267948966" xyz="-0.063 0 0"/>
      <geometry>
        <mesh filename="package://interbotix_xslocobot_descriptions/meshes/mobile_wx250s_meshes/gripper_bar.stl" scale="0.001 0.001 0.001"/>
      </geometry>
    </collision>
    <inertial>
      <origin rpy="0 0 1.5707963267948966" xyz="0.0096870000 0.0000008177 0.0049620000"/>
      <mass value="0.034199"/>
      <inertia ixx="0.0000074125" ixy="-0.0000000008" ixz="-0.0000000006" iyy="0.0000284300" iyz="-0.0000013889" izz="0.0000286000"/>
    </inertial>
  </link>
  <joint name="ee_bar" type="fixed">
    <axis xyz="1 0 0"/>
    <origin rpy="0 0 0" xyz="0.023 0 0"/>
    <parent link="_gripper_bar_link"/>
    <child link="_fingers_link"/>
  </joint>
  <link name="_fingers_link">
    <inertial>
      <mass value="0.001"/>
      <inertia ixx="0.001" ixy="0" ixz="0" iyy="0.001" iyz="0" izz="0.001"/>
    </inertial>
  </link>
  <!-- If the gripper fingers are being used, add those as well -->
  <joint name="left_finger" type="prismatic">
    <axis xyz="0 1 0"/>
    <limit effort="5.0" lower="-0.01" upper="0.037" velocity="1.0"/>
    <origin rpy="0 0 0" xyz="0 0 0"/>
    <parent link="_fingers_link"/>
    <child link="_left_finger_link"/>
    <dynamics damping="0.1" friction="0.1"/>
  </joint>
  <link name="_left_finger_link">
    <visual>
      <origin rpy="3.141592653589793 3.141592653589793 0" xyz="0 0.005 0"/>
      <geometry>
        <mesh filename="package://interbotix_xslocobot_descriptions/meshes/mobile_wx250s_meshes/gripper_finger.stl" scale="0.001 0.001 0.001"/>
      </geometry>
      <material name="interbotix_black"/>
    </visual>
    <collision>
      <origin rpy="3.141592653589793 3.141592653589793 0" xyz="0 0.005 0"/>
      <geometry>
        <mesh filename="package://interbotix_xslocobot_descriptions/meshes/mobile_wx250s_meshes/gripper_finger.stl" scale="0.001 0.001 0.001"/>
      </geometry>
    </collision>
    <inertial>
      <origin rpy="3.141592653589793 3.141592653589793 1.5707963267948966" xyz="0.0138160000 0 0"/>
      <mass value="0.016246"/>
      <inertia ixx="0.0000047310" ixy="-0.0000004560" ixz="0" iyy="0.0000015506" iyz="0" izz="0.0000037467"/>
    </inertial>
  </link>
  <joint name="right_finger" type="prismatic">
    <axis xyz="0 1 0"/>
    <limit effort="5.0" lower="-0.037" upper="0.01" velocity="1.0"/>
    <origin rpy="0 0 0" xyz="0 0 0"/>
    <parent link="_fingers_link"/>
    <child link="_right_finger_link"/>
    <dynamics damping="0.1" friction="0.1"/>
  </joint>
  <link name="_right_finger_link">
    <visual>
      <origin rpy="0 3.141592653589793 0" xyz="0 -0.005 0"/>
      <geometry>
        <mesh filename="package://interbotix_xslocobot_descriptions/meshes/mobile_wx250s_meshes/gripper_finger.stl" scale="0.001 0.001 0.001"/>
      </geometry>
      <material name="interbotix_black"/>
    </visual>
    <collision>
      <origin rpy="0 3.141592653589793 0" xyz="0 -0.005 0"/>
      <geometry>
        <mesh filename="package://interbotix_xslocobot_descriptions/meshes/mobile_wx250s_meshes/gripper_finger.stl" scale="0.001 0.001 0.001"/>
      </geometry>
    </collision>
    <inertial>
      <origin rpy="0 3.141592653589793 1.5707963267948966" xyz="0.0138160000 0  0"/>
      <mass value="0.016246"/>
      <inertia ixx="0.0000047310" ixy="0.0000004560" ixz="0" iyy="0.0000015506" iyz="0" izz="0.0000037467"/>
    </inertial>
  </link>
  <joint name="ee_gripper" type="fixed">
    <axis xyz="1 0 0"/>
    <origin rpy="0 0 0" xyz="0.027575 0 0"/>
    <parent link="_fingers_link"/>
    <child link="_ee_gripper_link"/>
  </joint>
  <link name="_ee_gripper_link">
    <inertial>
      <mass value="0.001"/>
      <inertia ixx="0.001" ixy="0" ixz="0" iyy="0.001" iyz="0" izz="0.001"/>
    </inertial>
  </link>
  <!--
      show_gripper_fingers -->
  <!--
    show_gripper_bar -->
  <!--
  use_gripper -->
  <gazebo reference="_arm_base_link">
    <material>Gazebo/DarkGrey</material>
    <dampingFactor>0.01</dampingFactor>
  </gazebo>
  <gazebo reference="arm_base_link_joint">
    <disableFixedJointLumping>true</disableFixedJointLumping>
  </gazebo>
  <gazebo reference="_shoulder_link">
    <material>Gazebo/DarkGrey</material>
    <dampingFactor>0.01</dampingFactor>
    <self_collide>true</self_collide>
  </gazebo>
  <gazebo reference="_upper_arm_link">
    <material>Gazebo/DarkGrey</material>
    <dampingFactor>0.01</dampingFactor>
    <self_collide>true</self_collide>
  </gazebo>
  <gazebo reference="_forearm_link">
    <material>Gazebo/DarkGrey</material>
    <dampingFactor>0.01</dampingFactor>
    <self_collide>true</self_collide>
  </gazebo>
  <gazebo reference="_upper_forearm_link">
    <material>Gazebo/DarkGrey</material>
    <dampingFactor>0.01</dampingFactor>
    <self_collide>true</self_collide>
  </gazebo>
  <gazebo reference="_lower_forearm_link">
    <material>Gazebo/DarkGrey</material>
    <dampingFactor>0.01</dampingFactor>
    <self_collide>true</self_collide>
  </gazebo>
  <gazebo reference="_wrist_link">
    <material>Gazebo/DarkGrey</material>
    <dampingFactor>0.01</dampingFactor>
    <self_collide>true</self_collide>
  </gazebo>
  <gazebo reference="_gripper_link">
    <material>Gazebo/DarkGrey</material>
    <dampingFactor>0.01</dampingFactor>
  </gazebo>
  <gazebo reference="_gripper_prop_link">
    <dampingFactor>0.01</dampingFactor>
    <material>Gazebo/DarkGrey</material>
  </gazebo>
  <gazebo reference="_gripper_bar_link">
    <material>Gazebo/DarkGrey</material>
  </gazebo>
  <gazebo reference="_left_finger_link">
    <material>Gazebo/DarkGrey</material>
    <dampingFactor>0.01</dampingFactor>
  </gazebo>
  <gazebo reference="_right_finger_link">
    <material>Gazebo/DarkGrey</material>
    <dampingFactor>0.01</dampingFactor>
  </gazebo>
  <gazebo reference="arm_base_link_joint">
    <disableFixedJointLumping>true</disableFixedJointLumping>
  </gazebo>
  <gazebo reference="plate">
    <disableFixedJointLumping>true</disableFixedJointLumping>
  </gazebo>
  <gazebo reference="ar_tag">
    <disableFixedJointLumping>true</disableFixedJointLumping>
  </gazebo>
  <gazebo reference="ee_arm">
    <disableFixedJointLumping>true</disableFixedJointLumping>
  </gazebo>
  <gazebo reference="gripper_bar">
    <disableFixedJointLumping>true</disableFixedJointLumping>
  </gazebo>
  <gazebo reference="ee_bar">
    <disableFixedJointLumping>true</disableFixedJointLumping>
  </gazebo>
  <gazebo reference="ee_gripper">
    <disableFixedJointLumping>true</disableFixedJointLumping>
  </gazebo>
  <!--
    arm_type == 'mobile_wx200' -->
  <!--
  arm_type != 'mobile_base' -->
  <!-- ********************************** Battery **********************************  -->
  <!-- base_type == 'kobuki' -->
  <!-- base_type == 'create3' -->
  <!-- ********************************** Camera Tower **********************************  -->
  <!--
  base_type == 'kobuki' -->
  <!--
  base_type == 'create3' -->
  <!-- ********************************** Pan & Tilt **********************************  -->
  <!--
  base_type == 'kobuki' -->
  <!--
  base_type == 'create3' -->
  <!-- ********************************** Lidar **********************************  -->
  <!--
    base_type == 'kobuki' -->
  <!--
    base_type == 'create3' -->
  <!--
  use_lidar -->
  <gazebo>
    <plugin filename="ign_ros2_control-system" name="ign_ros2_control::IgnitionROS2ControlPlugin">
      <robot_param>robot_description</robot_param>
      <parameters>
          /simply_ws/install/interbotix_xslocobot_sim/share/interbotix_xslocobot_sim/config/_version/locobot_wx250s_controllers.yaml
        </parameters>
    </plugin>
    <!-- Loads simulated sensors. -->
    <plugin filename="ignition-gazebo-sensors-system" name="ignition::gazebo::systems::Sensors">
    </plugin>
    <!-- <plugin
      filename="libignition-gazebo-diff-drive-system.so"
      name="ignition::gazebo::systems::DiffDrive">
      <left_joint>wheel_left_joint</left_joint>
      <right_joint>wheel_right_joint</right_joint>
      <wheel_separation>0.230</wheel_separation>
      <wheel_radius>0.035</wheel_radius>
      <odom_publish_frequency>62</odom_publish_frequency>
      <topic>cmd_vel</topic>
    </plugin> -->
    <!-- <plugin filename="ignition-gazebo-joint-state-publisher-system"
      name="ignition::gazebo::systems::JointStatePublisher" /> -->
  </gazebo>
  <!-- Defines hardware interface. -->
  <ros2_control name="SystemControl" type="system">
    <hardware>
      <plugin>ign_ros2_control/IgnitionSystem</plugin>
    </hardware>
    <joint name="waist">
      <command_interface name="position">
        <param name="min">-3.141582653589793</param>
        <param name="max">3.141582653589793</param>
      </command_interface>
      <state_interface name="position"/>
      <param name="initial_position">0</param>
    </joint>
    <joint name="shoulder">
      <command_interface name="position">
        <param name="min">-1.8849555921538759</param>
        <param name="max">1.9896753472735358</param>
      </command_interface>
      <state_interface name="position"/>
      <param name="initial_position">-1.1</param>
    </joint>
    <joint name="elbow">
      <command_interface name="position">
        <param name="min">-2.1467549799530254</param>
        <param name="max">1.6057029118347832</param>
      </command_interface>
      <state_interface name="position"/>
      <param name="initial_position">1.55</param>
    </joint>
    <joint name="forearm_roll">
      <command_interface name="position">
        <param name="min">-3.141582653589793</param>
        <param name="max">3.141582653589793</param>
      </command_interface>
      <state_interface name="position"/>
      <param name="initial_position">0</param>
    </joint>
    <joint name="wrist_angle">
      <command_interface name="position">
        <param name="min">-1.7453292519943295</param>
        <param name="max">2.1467549799530254</param>
      </command_interface>
      <state_interface name="position"/>
      <param name="initial_position">0.5</param>
    </joint>
    <joint name="wrist_rotate">
      <command_interface name="position">
        <param name="min">-3.141582653589793</param>
        <param name="max">3.141582653589793</param>
      </command_interface>
      <state_interface name="position"/>
      <param name="initial_position">0</param>
    </joint>
    <joint name="gripper">
      <command_interface name="position"/>
      <state_interface name="position"/>
    </joint>
    <joint name="left_finger">
      <command_interface name="position">
        <param name="min">-0.01</param>
        <param name="max">0.037</param>
      </command_interface>
      <state_interface name="position"/>
      <param name="initial_position">0.0195</param>
    </joint>
    <joint name="right_finger">
      <!-- <param name="mimic">left_finger</param>
            <param name="multiplier">1</param> -->
      <command_interface name="position">
        <param name="min">-0.037</param>
        <param name="max">0.01</param>
      </command_interface>
      <state_interface name="position"/>
      <param name="initial_position">-0.0195</param>
    </joint>
    <joint name="pan">
      <command_interface name="position"/>
      <state_interface name="position"/>
      <param name="initial_position">0</param>
      <!-- initial position for
      the GenericSystem -->
    </joint>
    <joint name="tilt">
      <command_interface name="position"/>
      <state_interface name="position"/>
      <param name="initial_position">0.8</param>
      <!-- initial position for
      the GenericSystem -->
    </joint>
    <!-- base_type ==
      'kobuki' -->
    <!-- TODO:(speralta): Move pan_and_tilt sensors here? -->
  </ros2_control>
</robot>
